2024-01-10 13:46:19,604 [INFO] django.utils.autoreload: C:\Users\User\PycharmProjects\python_django\mysite\mysite\settings.py changed, reloading.
2024-01-10 13:46:20,695 [INFO] django.utils.autoreload: Watching for file changes with StatReloader
2024-01-10 16:18:19,546 [INFO] django.utils.autoreload: Watching for file changes with StatReloader
2024-01-11 17:05:38,613 [INFO] django.utils.autoreload: Watching for file changes with StatReloader
2024-01-11 17:10:40,507 [INFO] django.utils.autoreload: Watching for file changes with StatReloader
2024-01-11 17:11:40,016 [INFO] django.utils.autoreload: Watching for file changes with StatReloader
2024-01-11 17:16:20,850 [INFO] django.utils.autoreload: Watching for file changes with StatReloader
2024-01-11 17:19:41,481 [INFO] django.utils.autoreload: C:\Users\shuri\PycharmProjects\python_django\mysite\mysite\settings.py changed, reloading.
2024-01-11 17:19:43,013 [INFO] django.utils.autoreload: Watching for file changes with StatReloader
2024-01-11 17:20:31,620 [INFO] django.utils.autoreload: C:\Users\shuri\PycharmProjects\python_django\mysite\mysite\settings.py changed, reloading.
2024-01-11 17:20:33,727 [INFO] django.utils.autoreload: Watching for file changes with StatReloader
2024-01-11 17:22:12,292 [INFO] django.utils.autoreload: Watching for file changes with StatReloader
2024-01-11 17:26:53,929 [INFO] django.utils.autoreload: Watching for file changes with StatReloader
2024-01-11 17:30:17,691 [INFO] django.utils.autoreload: C:\Users\shuri\PycharmProjects\python_django\mysite\mysite\settings.py changed, reloading.
2024-01-11 17:30:19,261 [INFO] django.utils.autoreload: Watching for file changes with StatReloader
2024-01-11 17:30:32,751 [INFO] django.utils.autoreload: C:\Users\shuri\PycharmProjects\python_django\mysite\mysite\settings.py changed, reloading.
2024-01-11 17:30:34,188 [INFO] django.utils.autoreload: Watching for file changes with StatReloader
2024-01-11 17:30:43,478 [INFO] django.utils.autoreload: C:\Users\shuri\PycharmProjects\python_django\mysite\mysite\settings.py changed, reloading.
2024-01-11 17:30:44,341 [INFO] django.utils.autoreload: Watching for file changes with StatReloader
2024-01-11 17:31:33,065 [INFO] django.utils.autoreload: Watching for file changes with StatReloader
2024-01-11 17:33:52,073 [INFO] django.utils.autoreload: C:\Users\shuri\PycharmProjects\python_django\mysite\mysite\settings.py changed, reloading.
2024-01-11 17:33:53,620 [INFO] django.utils.autoreload: Watching for file changes with StatReloader
2024-01-11 17:38:16,968 [INFO] django.utils.autoreload: C:\Users\shuri\PycharmProjects\python_django\mysite\mysite\settings.py changed, reloading.
2024-01-11 17:38:19,041 [INFO] django.utils.autoreload: Watching for file changes with StatReloader
2024-01-11 17:38:29,758 [INFO] django.utils.autoreload: C:\Users\shuri\PycharmProjects\python_django\mysite\mysite\settings.py changed, reloading.
2024-01-11 17:38:31,376 [INFO] django.utils.autoreload: Watching for file changes with StatReloader
2024-01-11 17:45:35,219 [INFO] django.utils.autoreload: Watching for file changes with StatReloader
2024-01-11 17:52:51,935 [INFO] django.utils.autoreload: Watching for file changes with StatReloader
2024-01-11 18:01:11,416 [INFO] django.utils.autoreload: C:\Users\shuri\PycharmProjects\python_django\mysite\mysite\settings.py changed, reloading.
2024-01-11 18:01:13,543 [INFO] django.utils.autoreload: Watching for file changes with StatReloader
2024-01-11 18:06:08,269 [INFO] django.utils.autoreload: Watching for file changes with StatReloader
2024-01-11 18:07:01,019 [INFO] django.utils.autoreload: C:\Users\shuri\PycharmProjects\python_django\mysite\mysite\settings.py changed, reloading.
2024-01-11 18:07:02,069 [INFO] django.utils.autoreload: Watching for file changes with StatReloader
2024-01-11 18:20:31,387 [INFO] django.utils.autoreload: Watching for file changes with StatReloader
2024-01-11 18:24:12,107 [INFO] django.utils.autoreload: Watching for file changes with StatReloader
2024-01-11 18:24:20,345 [WARNING] django.request: Not Found: /
2024-01-11 18:24:21,905 [WARNING] django.request: Not Found: /favicon.ico
2024-01-11 18:25:44,085 [INFO] shopapp.views: Rendering shop index
2024-01-12 11:48:55,194 [INFO] django.utils.autoreload: C:\Users\shuri\PycharmProjects\python_django\mysite\mysite\settings.py changed, reloading.
2024-01-12 11:48:58,438 [INFO] django.utils.autoreload: Watching for file changes with StatReloader
2024-01-19 12:32:51,596 [INFO] django.utils.autoreload: Watching for file changes with StatReloader
2024-01-19 12:32:58,865 [INFO] shopapp.views: Rendering shop index
2024-01-19 12:33:19,879 [WARNING] django.request: Not Found: /ru/shop/products/export
2024-01-19 12:35:21,305 [WARNING] django.request: Not Found: /ru/shop/products/export
2024-01-19 12:44:06,225 [ERROR] django.request: Internal Server Error: /ru/shop/orders/export/
Traceback (most recent call last):
  File "C:\Users\shuri\AppData\Local\Programs\Python\Python39\lib\site-packages\django\core\handlers\exception.py", line 55, in inner
    response = get_response(request)
  File "C:\Users\shuri\AppData\Local\Programs\Python\Python39\lib\site-packages\django\core\handlers\base.py", line 197, in _get_response
    response = wrapped_callback(request, *callback_args, **callback_kwargs)
  File "C:\Users\shuri\AppData\Local\Programs\Python\Python39\lib\site-packages\django\views\generic\base.py", line 84, in view
    return self.dispatch(request, *args, **kwargs)
  File "C:\Users\shuri\AppData\Local\Programs\Python\Python39\lib\site-packages\django\views\generic\base.py", line 119, in dispatch
    return handler(request, *args, **kwargs)
  File "C:\Users\shuri\PycharmProjects\python_django\mysite\shopapp\views.py", line 260, in get
    return JsonResponse({'orders': orders_data})
  File "C:\Users\shuri\AppData\Local\Programs\Python\Python39\lib\site-packages\django\http\response.py", line 653, in __init__
    data = json.dumps(data, cls=encoder, **json_dumps_params)
  File "C:\Users\shuri\AppData\Local\Programs\Python\Python39\lib\json\__init__.py", line 234, in dumps
    return cls(
  File "C:\Users\shuri\AppData\Local\Programs\Python\Python39\lib\json\encoder.py", line 199, in encode
    chunks = self.iterencode(o, _one_shot=True)
  File "C:\Users\shuri\AppData\Local\Programs\Python\Python39\lib\json\encoder.py", line 257, in iterencode
    return _iterencode(o, 0)
  File "C:\Users\shuri\AppData\Local\Programs\Python\Python39\lib\site-packages\django\core\serializers\json.py", line 106, in default
    return super().default(o)
  File "C:\Users\shuri\AppData\Local\Programs\Python\Python39\lib\json\encoder.py", line 179, in default
    raise TypeError(f'Object of type {o.__class__.__name__} '
TypeError: Object of type User is not JSON serializable
2024-01-19 12:55:29,421 [INFO] django.utils.autoreload: Watching for file changes with StatReloader
2024-01-19 12:55:36,649 [INFO] shopapp.views: Rendering shop index
2024-01-24 16:22:39,749 [INFO] django.utils.autoreload: Watching for file changes with StatReloader
2024-01-24 16:23:06,731 [INFO] shopapp.views: Rendering shop index
2024-01-24 16:38:20,624 [INFO] django.utils.autoreload: Watching for file changes with StatReloader
2024-01-24 16:38:31,318 [WARNING] django.request: Not Found: /favicon.ico
2024-01-24 16:58:26,517 [INFO] django.utils.autoreload: C:\Users\shuri\PycharmProjects\python_django\mysite\shopapp\admin.py changed, reloading.
2024-01-24 16:58:29,358 [INFO] django.utils.autoreload: Watching for file changes with StatReloader
2024-01-24 16:58:32,516 [ERROR] django.request: Internal Server Error: /admin/shopapp/product/
Traceback (most recent call last):
  File "C:\Users\shuri\AppData\Local\Programs\Python\Python39\lib\site-packages\django\core\handlers\exception.py", line 55, in inner
    response = get_response(request)
  File "C:\Users\shuri\AppData\Local\Programs\Python\Python39\lib\site-packages\django\core\handlers\base.py", line 220, in _get_response
    response = response.render()
  File "C:\Users\shuri\AppData\Local\Programs\Python\Python39\lib\site-packages\django\template\response.py", line 114, in render
    self.content = self.rendered_content
  File "C:\Users\shuri\AppData\Local\Programs\Python\Python39\lib\site-packages\django\template\response.py", line 92, in rendered_content
    return template.render(context, self._request)
  File "C:\Users\shuri\AppData\Local\Programs\Python\Python39\lib\site-packages\django\template\backends\django.py", line 62, in render
    return self.template.render(context)
  File "C:\Users\shuri\AppData\Local\Programs\Python\Python39\lib\site-packages\django\template\base.py", line 175, in render
    return self._render(context)
  File "C:\Users\shuri\AppData\Local\Programs\Python\Python39\lib\site-packages\django\test\utils.py", line 111, in instrumented_test_render
    return self.nodelist.render(context)
  File "C:\Users\shuri\AppData\Local\Programs\Python\Python39\lib\site-packages\django\template\base.py", line 1005, in render
    return SafeString("".join([node.render_annotated(context) for node in self]))
  File "C:\Users\shuri\AppData\Local\Programs\Python\Python39\lib\site-packages\django\template\base.py", line 1005, in <listcomp>
    return SafeString("".join([node.render_annotated(context) for node in self]))
  File "C:\Users\shuri\AppData\Local\Programs\Python\Python39\lib\site-packages\django\template\base.py", line 966, in render_annotated
    return self.render(context)
  File "C:\Users\shuri\AppData\Local\Programs\Python\Python39\lib\site-packages\django\template\loader_tags.py", line 157, in render
    return compiled_parent._render(context)
  File "C:\Users\shuri\AppData\Local\Programs\Python\Python39\lib\site-packages\django\test\utils.py", line 111, in instrumented_test_render
    return self.nodelist.render(context)
  File "C:\Users\shuri\AppData\Local\Programs\Python\Python39\lib\site-packages\django\template\base.py", line 1005, in render
    return SafeString("".join([node.render_annotated(context) for node in self]))
  File "C:\Users\shuri\AppData\Local\Programs\Python\Python39\lib\site-packages\django\template\base.py", line 1005, in <listcomp>
    return SafeString("".join([node.render_annotated(context) for node in self]))
  File "C:\Users\shuri\AppData\Local\Programs\Python\Python39\lib\site-packages\django\template\base.py", line 966, in render_annotated
    return self.render(context)
  File "C:\Users\shuri\AppData\Local\Programs\Python\Python39\lib\site-packages\django\template\loader_tags.py", line 157, in render
    return compiled_parent._render(context)
  File "C:\Users\shuri\AppData\Local\Programs\Python\Python39\lib\site-packages\django\test\utils.py", line 111, in instrumented_test_render
    return self.nodelist.render(context)
  File "C:\Users\shuri\AppData\Local\Programs\Python\Python39\lib\site-packages\django\template\base.py", line 1005, in render
    return SafeString("".join([node.render_annotated(context) for node in self]))
  File "C:\Users\shuri\AppData\Local\Programs\Python\Python39\lib\site-packages\django\template\base.py", line 1005, in <listcomp>
    return SafeString("".join([node.render_annotated(context) for node in self]))
  File "C:\Users\shuri\AppData\Local\Programs\Python\Python39\lib\site-packages\django\template\base.py", line 966, in render_annotated
    return self.render(context)
  File "C:\Users\shuri\AppData\Local\Programs\Python\Python39\lib\site-packages\django\template\loader_tags.py", line 157, in render
    return compiled_parent._render(context)
  File "C:\Users\shuri\AppData\Local\Programs\Python\Python39\lib\site-packages\django\test\utils.py", line 111, in instrumented_test_render
    return self.nodelist.render(context)
  File "C:\Users\shuri\AppData\Local\Programs\Python\Python39\lib\site-packages\django\template\base.py", line 1005, in render
    return SafeString("".join([node.render_annotated(context) for node in self]))
  File "C:\Users\shuri\AppData\Local\Programs\Python\Python39\lib\site-packages\django\template\base.py", line 1005, in <listcomp>
    return SafeString("".join([node.render_annotated(context) for node in self]))
  File "C:\Users\shuri\AppData\Local\Programs\Python\Python39\lib\site-packages\django\template\base.py", line 966, in render_annotated
    return self.render(context)
  File "C:\Users\shuri\AppData\Local\Programs\Python\Python39\lib\site-packages\django\template\loader_tags.py", line 63, in render
    result = block.nodelist.render(context)
  File "C:\Users\shuri\AppData\Local\Programs\Python\Python39\lib\site-packages\django\template\base.py", line 1005, in render
    return SafeString("".join([node.render_annotated(context) for node in self]))
  File "C:\Users\shuri\AppData\Local\Programs\Python\Python39\lib\site-packages\django\template\base.py", line 1005, in <listcomp>
    return SafeString("".join([node.render_annotated(context) for node in self]))
  File "C:\Users\shuri\AppData\Local\Programs\Python\Python39\lib\site-packages\django\template\base.py", line 966, in render_annotated
    return self.render(context)
  File "C:\Users\shuri\AppData\Local\Programs\Python\Python39\lib\site-packages\django\template\loader_tags.py", line 63, in render
    result = block.nodelist.render(context)
  File "C:\Users\shuri\AppData\Local\Programs\Python\Python39\lib\site-packages\django\template\base.py", line 1005, in render
    return SafeString("".join([node.render_annotated(context) for node in self]))
  File "C:\Users\shuri\AppData\Local\Programs\Python\Python39\lib\site-packages\django\template\base.py", line 1005, in <listcomp>
    return SafeString("".join([node.render_annotated(context) for node in self]))
  File "C:\Users\shuri\AppData\Local\Programs\Python\Python39\lib\site-packages\django\template\base.py", line 966, in render_annotated
    return self.render(context)
  File "C:\Users\shuri\AppData\Local\Programs\Python\Python39\lib\site-packages\django\template\loader_tags.py", line 63, in render
    result = block.nodelist.render(context)
  File "C:\Users\shuri\AppData\Local\Programs\Python\Python39\lib\site-packages\django\template\base.py", line 1005, in render
    return SafeString("".join([node.render_annotated(context) for node in self]))
  File "C:\Users\shuri\AppData\Local\Programs\Python\Python39\lib\site-packages\django\template\base.py", line 1005, in <listcomp>
    return SafeString("".join([node.render_annotated(context) for node in self]))
  File "C:\Users\shuri\AppData\Local\Programs\Python\Python39\lib\site-packages\django\template\base.py", line 966, in render_annotated
    return self.render(context)
  File "C:\Users\shuri\AppData\Local\Programs\Python\Python39\lib\site-packages\django\template\defaulttags.py", line 472, in render
    url = reverse(view_name, args=args, kwargs=kwargs, current_app=current_app)
  File "C:\Users\shuri\AppData\Local\Programs\Python\Python39\lib\site-packages\django\urls\base.py", line 88, in reverse
    return resolver._reverse_with_prefix(view, prefix, *args, **kwargs)
  File "C:\Users\shuri\AppData\Local\Programs\Python\Python39\lib\site-packages\django\urls\resolvers.py", line 828, in _reverse_with_prefix
    raise NoReverseMatch(msg)
django.urls.exceptions.NoReverseMatch: Reverse for 'products_changelist.html' not found. 'products_changelist.html' is not a valid view function or pattern name.
2024-01-26 11:32:37,578 [INFO] django.utils.autoreload: Watching for file changes with StatReloader
2024-01-26 11:32:54,823 [WARNING] django.request: Not Found: /favicon.ico
2024-01-26 12:00:49,116 [INFO] django.utils.autoreload: C:\Users\shuri\PycharmProjects\python_django\mysite\shopapp\admin.py changed, reloading.
2024-01-26 12:00:53,605 [INFO] django.utils.autoreload: Watching for file changes with StatReloader
2024-01-26 12:04:12,840 [INFO] django.utils.autoreload: C:\Users\shuri\PycharmProjects\python_django\mysite\shopapp\views.py changed, reloading.
2024-01-26 12:04:14,346 [INFO] django.utils.autoreload: Watching for file changes with StatReloader
2024-01-26 12:05:58,922 [INFO] django.utils.autoreload: C:\Users\shuri\PycharmProjects\python_django\mysite\shopapp\common.py changed, reloading.
2024-01-26 12:05:59,866 [INFO] django.utils.autoreload: Watching for file changes with StatReloader
2024-01-26 12:07:58,450 [INFO] django.utils.autoreload: C:\Users\shuri\PycharmProjects\python_django\mysite\shopapp\views.py changed, reloading.
2024-01-26 12:07:59,448 [INFO] django.utils.autoreload: Watching for file changes with StatReloader
2024-02-01 09:41:55,897 [INFO] django.utils.autoreload: C:\Users\shuri\PycharmProjects\python_django\mysite\mysite\urls.py changed, reloading.
2024-02-01 09:41:57,662 [INFO] django.utils.autoreload: Watching for file changes with StatReloader
2024-02-01 09:53:13,688 [INFO] django.utils.autoreload: Watching for file changes with StatReloader
2024-02-01 09:53:43,024 [ERROR] django.request: Internal Server Error: /ru/blog/articles/
Traceback (most recent call last):
  File "C:\Users\shuri\AppData\Local\Programs\Python\Python39\lib\site-packages\django\core\handlers\exception.py", line 55, in inner
    response = get_response(request)
  File "C:\Users\shuri\AppData\Local\Programs\Python\Python39\lib\site-packages\django\core\handlers\base.py", line 220, in _get_response
    response = response.render()
  File "C:\Users\shuri\AppData\Local\Programs\Python\Python39\lib\site-packages\django\template\response.py", line 114, in render
    self.content = self.rendered_content
  File "C:\Users\shuri\AppData\Local\Programs\Python\Python39\lib\site-packages\django\template\response.py", line 90, in rendered_content
    template = self.resolve_template(self.template_name)
  File "C:\Users\shuri\AppData\Local\Programs\Python\Python39\lib\site-packages\django\template\response.py", line 72, in resolve_template
    return select_template(template, using=self.using)
  File "C:\Users\shuri\AppData\Local\Programs\Python\Python39\lib\site-packages\django\template\loader.py", line 47, in select_template
    raise TemplateDoesNotExist(", ".join(template_name_list), chain=chain)
django.template.exceptions.TemplateDoesNotExist: blogapp/article_list.html
2024-02-01 09:53:53,363 [WARNING] django.request: Not Found: /ru/blog/
2024-02-01 09:54:03,146 [WARNING] django.request: Not Found: /blog/
2024-02-01 09:55:16,248 [ERROR] django.request: Internal Server Error: /ru/blog/articles/
Traceback (most recent call last):
  File "C:\Users\shuri\AppData\Local\Programs\Python\Python39\lib\site-packages\django\core\handlers\exception.py", line 55, in inner
    response = get_response(request)
  File "C:\Users\shuri\AppData\Local\Programs\Python\Python39\lib\site-packages\django\core\handlers\base.py", line 220, in _get_response
    response = response.render()
  File "C:\Users\shuri\AppData\Local\Programs\Python\Python39\lib\site-packages\django\template\response.py", line 114, in render
    self.content = self.rendered_content
  File "C:\Users\shuri\AppData\Local\Programs\Python\Python39\lib\site-packages\django\template\response.py", line 90, in rendered_content
    template = self.resolve_template(self.template_name)
  File "C:\Users\shuri\AppData\Local\Programs\Python\Python39\lib\site-packages\django\template\response.py", line 72, in resolve_template
    return select_template(template, using=self.using)
  File "C:\Users\shuri\AppData\Local\Programs\Python\Python39\lib\site-packages\django\template\loader.py", line 47, in select_template
    raise TemplateDoesNotExist(", ".join(template_name_list), chain=chain)
django.template.exceptions.TemplateDoesNotExist: blogapp/article_list.html
2024-02-01 09:57:03,390 [INFO] django.utils.autoreload: C:\Users\shuri\PycharmProjects\python_django\mysite\blogapp\urls.py changed, reloading.
2024-02-01 09:57:08,176 [INFO] django.utils.autoreload: Watching for file changes with StatReloader
2024-02-01 10:06:10,746 [INFO] django.utils.autoreload: Watching for file changes with StatReloader
2024-02-01 10:08:37,395 [INFO] django.utils.autoreload: C:\Users\shuri\PycharmProjects\python_django\mysite\blogapp\admin.py changed, reloading.
2024-02-01 10:08:39,272 [INFO] django.utils.autoreload: Watching for file changes with StatReloader
2024-02-01 10:10:16,868 [WARNING] django.request: Not Found: /blogapp/articles/
2024-02-01 10:10:27,167 [WARNING] django.request: Not Found: /blogp/articles/
2024-02-01 10:12:45,330 [ERROR] django.request: Internal Server Error: /ru/blog/articles_detail/1/
Traceback (most recent call last):
  File "C:\Users\shuri\AppData\Local\Programs\Python\Python39\lib\site-packages\django\core\handlers\exception.py", line 55, in inner
    response = get_response(request)
  File "C:\Users\shuri\AppData\Local\Programs\Python\Python39\lib\site-packages\django\core\handlers\base.py", line 220, in _get_response
    response = response.render()
  File "C:\Users\shuri\AppData\Local\Programs\Python\Python39\lib\site-packages\django\template\response.py", line 114, in render
    self.content = self.rendered_content
  File "C:\Users\shuri\AppData\Local\Programs\Python\Python39\lib\site-packages\django\template\response.py", line 90, in rendered_content
    template = self.resolve_template(self.template_name)
  File "C:\Users\shuri\AppData\Local\Programs\Python\Python39\lib\site-packages\django\template\response.py", line 72, in resolve_template
    return select_template(template, using=self.using)
  File "C:\Users\shuri\AppData\Local\Programs\Python\Python39\lib\site-packages\django\template\loader.py", line 47, in select_template
    raise TemplateDoesNotExist(", ".join(template_name_list), chain=chain)
django.template.exceptions.TemplateDoesNotExist: blogapp/article_detail.html
2024-02-01 10:13:09,227 [ERROR] django.request: Internal Server Error: /ru/blog/articles_detail/2/
Traceback (most recent call last):
  File "C:\Users\shuri\AppData\Local\Programs\Python\Python39\lib\site-packages\django\core\handlers\exception.py", line 55, in inner
    response = get_response(request)
  File "C:\Users\shuri\AppData\Local\Programs\Python\Python39\lib\site-packages\django\core\handlers\base.py", line 220, in _get_response
    response = response.render()
  File "C:\Users\shuri\AppData\Local\Programs\Python\Python39\lib\site-packages\django\template\response.py", line 114, in render
    self.content = self.rendered_content
  File "C:\Users\shuri\AppData\Local\Programs\Python\Python39\lib\site-packages\django\template\response.py", line 90, in rendered_content
    template = self.resolve_template(self.template_name)
  File "C:\Users\shuri\AppData\Local\Programs\Python\Python39\lib\site-packages\django\template\response.py", line 72, in resolve_template
    return select_template(template, using=self.using)
  File "C:\Users\shuri\AppData\Local\Programs\Python\Python39\lib\site-packages\django\template\loader.py", line 47, in select_template
    raise TemplateDoesNotExist(", ".join(template_name_list), chain=chain)
django.template.exceptions.TemplateDoesNotExist: blogapp/article_detail.html
2024-02-01 10:16:32,432 [ERROR] django.request: Internal Server Error: /ru/blog/articles_detail/2/
Traceback (most recent call last):
  File "C:\Users\shuri\AppData\Local\Programs\Python\Python39\lib\site-packages\django\core\handlers\exception.py", line 55, in inner
    response = get_response(request)
  File "C:\Users\shuri\AppData\Local\Programs\Python\Python39\lib\site-packages\django\core\handlers\base.py", line 220, in _get_response
    response = response.render()
  File "C:\Users\shuri\AppData\Local\Programs\Python\Python39\lib\site-packages\django\template\response.py", line 114, in render
    self.content = self.rendered_content
  File "C:\Users\shuri\AppData\Local\Programs\Python\Python39\lib\site-packages\django\template\response.py", line 90, in rendered_content
    template = self.resolve_template(self.template_name)
  File "C:\Users\shuri\AppData\Local\Programs\Python\Python39\lib\site-packages\django\template\response.py", line 72, in resolve_template
    return select_template(template, using=self.using)
  File "C:\Users\shuri\AppData\Local\Programs\Python\Python39\lib\site-packages\django\template\loader.py", line 42, in select_template
    return engine.get_template(template_name)
  File "C:\Users\shuri\AppData\Local\Programs\Python\Python39\lib\site-packages\django\template\backends\django.py", line 34, in get_template
    return Template(self.engine.get_template(template_name), self)
  File "C:\Users\shuri\AppData\Local\Programs\Python\Python39\lib\site-packages\django\template\engine.py", line 175, in get_template
    template, origin = self.find_template(template_name)
  File "C:\Users\shuri\AppData\Local\Programs\Python\Python39\lib\site-packages\django\template\engine.py", line 157, in find_template
    template = loader.get_template(name, skip=skip)
  File "C:\Users\shuri\AppData\Local\Programs\Python\Python39\lib\site-packages\django\template\loaders\cached.py", line 57, in get_template
    template = super().get_template(template_name, skip)
  File "C:\Users\shuri\AppData\Local\Programs\Python\Python39\lib\site-packages\django\template\loaders\base.py", line 28, in get_template
    return Template(
  File "C:\Users\shuri\AppData\Local\Programs\Python\Python39\lib\site-packages\django\template\base.py", line 154, in __init__
    self.nodelist = self.compile_nodelist()
  File "C:\Users\shuri\AppData\Local\Programs\Python\Python39\lib\site-packages\django\template\base.py", line 200, in compile_nodelist
    return parser.parse()
  File "C:\Users\shuri\AppData\Local\Programs\Python\Python39\lib\site-packages\django\template\base.py", line 513, in parse
    raise self.error(token, e)
  File "C:\Users\shuri\AppData\Local\Programs\Python\Python39\lib\site-packages\django\template\base.py", line 511, in parse
    compiled_result = compile_func(self, token)
  File "C:\Users\shuri\AppData\Local\Programs\Python\Python39\lib\site-packages\django\template\loader_tags.py", line 293, in do_extends
    nodelist = parser.parse()
  File "C:\Users\shuri\AppData\Local\Programs\Python\Python39\lib\site-packages\django\template\base.py", line 513, in parse
    raise self.error(token, e)
  File "C:\Users\shuri\AppData\Local\Programs\Python\Python39\lib\site-packages\django\template\base.py", line 511, in parse
    compiled_result = compile_func(self, token)
  File "C:\Users\shuri\AppData\Local\Programs\Python\Python39\lib\site-packages\django\template\loader_tags.py", line 232, in do_block
    nodelist = parser.parse(("endblock",))
  File "C:\Users\shuri\AppData\Local\Programs\Python\Python39\lib\site-packages\django\template\base.py", line 518, in parse
    self.unclosed_block_tag(parse_until)
  File "C:\Users\shuri\AppData\Local\Programs\Python\Python39\lib\site-packages\django\template\base.py", line 581, in unclosed_block_tag
    raise self.error(token, msg)
django.template.exceptions.TemplateSyntaxError: Unclosed tag on line 17: 'block'. Looking for one of: endblock.
2024-02-01 10:17:14,076 [ERROR] django.request: Internal Server Error: /ru/blog/articles_detail/2/
Traceback (most recent call last):
  File "C:\Users\shuri\AppData\Local\Programs\Python\Python39\lib\site-packages\django\urls\base.py", line 71, in reverse
    extra, resolver = resolver.namespace_dict[ns]
KeyError: 'bloapp'

During handling of the above exception, another exception occurred:

Traceback (most recent call last):
  File "C:\Users\shuri\AppData\Local\Programs\Python\Python39\lib\site-packages\django\core\handlers\exception.py", line 55, in inner
    response = get_response(request)
  File "C:\Users\shuri\AppData\Local\Programs\Python\Python39\lib\site-packages\django\core\handlers\base.py", line 220, in _get_response
    response = response.render()
  File "C:\Users\shuri\AppData\Local\Programs\Python\Python39\lib\site-packages\django\template\response.py", line 114, in render
    self.content = self.rendered_content
  File "C:\Users\shuri\AppData\Local\Programs\Python\Python39\lib\site-packages\django\template\response.py", line 92, in rendered_content
    return template.render(context, self._request)
  File "C:\Users\shuri\AppData\Local\Programs\Python\Python39\lib\site-packages\django\template\backends\django.py", line 62, in render
    return self.template.render(context)
  File "C:\Users\shuri\AppData\Local\Programs\Python\Python39\lib\site-packages\django\template\base.py", line 175, in render
    return self._render(context)
  File "C:\Users\shuri\AppData\Local\Programs\Python\Python39\lib\site-packages\django\test\utils.py", line 111, in instrumented_test_render
    return self.nodelist.render(context)
  File "C:\Users\shuri\AppData\Local\Programs\Python\Python39\lib\site-packages\django\template\base.py", line 1005, in render
    return SafeString("".join([node.render_annotated(context) for node in self]))
  File "C:\Users\shuri\AppData\Local\Programs\Python\Python39\lib\site-packages\django\template\base.py", line 1005, in <listcomp>
    return SafeString("".join([node.render_annotated(context) for node in self]))
  File "C:\Users\shuri\AppData\Local\Programs\Python\Python39\lib\site-packages\django\template\base.py", line 966, in render_annotated
    return self.render(context)
  File "C:\Users\shuri\AppData\Local\Programs\Python\Python39\lib\site-packages\django\template\loader_tags.py", line 157, in render
    return compiled_parent._render(context)
  File "C:\Users\shuri\AppData\Local\Programs\Python\Python39\lib\site-packages\django\test\utils.py", line 111, in instrumented_test_render
    return self.nodelist.render(context)
  File "C:\Users\shuri\AppData\Local\Programs\Python\Python39\lib\site-packages\django\template\base.py", line 1005, in render
    return SafeString("".join([node.render_annotated(context) for node in self]))
  File "C:\Users\shuri\AppData\Local\Programs\Python\Python39\lib\site-packages\django\template\base.py", line 1005, in <listcomp>
    return SafeString("".join([node.render_annotated(context) for node in self]))
  File "C:\Users\shuri\AppData\Local\Programs\Python\Python39\lib\site-packages\django\template\base.py", line 966, in render_annotated
    return self.render(context)
  File "C:\Users\shuri\AppData\Local\Programs\Python\Python39\lib\site-packages\django\template\loader_tags.py", line 63, in render
    result = block.nodelist.render(context)
  File "C:\Users\shuri\AppData\Local\Programs\Python\Python39\lib\site-packages\django\template\base.py", line 1005, in render
    return SafeString("".join([node.render_annotated(context) for node in self]))
  File "C:\Users\shuri\AppData\Local\Programs\Python\Python39\lib\site-packages\django\template\base.py", line 1005, in <listcomp>
    return SafeString("".join([node.render_annotated(context) for node in self]))
  File "C:\Users\shuri\AppData\Local\Programs\Python\Python39\lib\site-packages\django\template\base.py", line 966, in render_annotated
    return self.render(context)
  File "C:\Users\shuri\AppData\Local\Programs\Python\Python39\lib\site-packages\django\template\defaulttags.py", line 472, in render
    url = reverse(view_name, args=args, kwargs=kwargs, current_app=current_app)
  File "C:\Users\shuri\AppData\Local\Programs\Python\Python39\lib\site-packages\django\urls\base.py", line 82, in reverse
    raise NoReverseMatch("%s is not a registered namespace" % key)
django.urls.exceptions.NoReverseMatch: 'bloapp' is not a registered namespace
2024-02-01 10:27:16,091 [INFO] django.utils.autoreload: C:\Users\shuri\PycharmProjects\python_django\mysite\blogapp\urls.py changed, reloading.
2024-02-01 10:27:18,034 [INFO] django.utils.autoreload: Watching for file changes with StatReloader
2024-02-02 11:05:34,178 [INFO] django.utils.autoreload: C:\Users\shuri\PycharmProjects\python_django\mysite\mysite\urls.py changed, reloading.
2024-02-02 11:05:38,182 [INFO] django.utils.autoreload: Watching for file changes with StatReloader
2024-02-02 11:06:14,826 [INFO] django.utils.autoreload: C:\Users\shuri\PycharmProjects\python_django\mysite\mysite\settings.py changed, reloading.
2024-02-02 11:06:16,426 [INFO] django.utils.autoreload: Watching for file changes with StatReloader
2024-02-02 11:08:28,932 [INFO] shopapp.views: Rendering shop index
2024-02-06 15:29:45,050 [INFO] django.utils.autoreload: Watching for file changes with StatReloader
2024-02-06 15:30:02,918 [INFO] shopapp.views: Rendering shop index
2024-02-08 11:04:38,919 [INFO] django.utils.autoreload: Watching for file changes with StatReloader
2024-02-08 11:05:25,032 [INFO] django.utils.autoreload: C:\Users\shuri\PycharmProjects\python_django\mysite\myauth\views.py changed, reloading.
2024-02-08 11:05:27,029 [INFO] django.utils.autoreload: Watching for file changes with StatReloader
2024-02-08 11:06:00,139 [INFO] django.utils.autoreload: C:\Users\shuri\PycharmProjects\python_django\mysite\myauth\views.py changed, reloading.
2024-02-08 11:06:02,338 [INFO] django.utils.autoreload: Watching for file changes with StatReloader
2024-02-08 11:06:38,545 [INFO] django.utils.autoreload: C:\Users\shuri\PycharmProjects\python_django\mysite\mysite\settings.py changed, reloading.
2024-02-08 11:06:41,257 [INFO] django.utils.autoreload: Watching for file changes with StatReloader
2024-02-08 11:06:57,808 [INFO] django.utils.autoreload: C:\Users\shuri\PycharmProjects\python_django\mysite\myauth\views.py changed, reloading.
2024-02-08 11:07:02,293 [INFO] django.utils.autoreload: Watching for file changes with StatReloader
2024-02-08 11:13:15,997 [INFO] django.utils.autoreload: C:\Users\shuri\PycharmProjects\python_django\mysite\shopapp\views.py changed, reloading.
2024-02-08 11:13:18,970 [INFO] django.utils.autoreload: Watching for file changes with StatReloader
2024-02-08 11:13:24,541 [INFO] shopapp.views: Rendering shop index
2024-02-08 11:13:29,026 [INFO] shopapp.views: Rendering shop index
2024-02-08 11:13:31,045 [INFO] shopapp.views: Rendering shop index
2024-02-08 11:18:19,715 [INFO] django.utils.autoreload: C:\Users\shuri\PycharmProjects\python_django\mysite\shopapp\views.py changed, reloading.
2024-02-08 11:18:22,391 [INFO] django.utils.autoreload: Watching for file changes with StatReloader
2024-02-08 11:18:25,493 [INFO] shopapp.views: Rendering shop index
2024-02-08 11:21:32,241 [INFO] django.utils.autoreload: C:\Users\shuri\PycharmProjects\python_django\mysite\shopapp\views.py changed, reloading.
2024-02-08 11:21:34,676 [INFO] django.utils.autoreload: Watching for file changes with StatReloader
2024-02-08 11:21:40,458 [INFO] shopapp.views: Rendering shop index
2024-02-08 11:21:44,989 [INFO] shopapp.views: Rendering shop index
2024-02-08 11:21:46,045 [INFO] shopapp.views: Rendering shop index
2024-02-08 11:26:22,765 [ERROR] django.request: Internal Server Error: /ru/myauth/about-me/
Traceback (most recent call last):
  File "C:\Users\shuri\AppData\Local\Programs\Python\Python39\lib\site-packages\django\core\handlers\exception.py", line 55, in inner
    response = get_response(request)
  File "C:\Users\shuri\AppData\Local\Programs\Python\Python39\lib\site-packages\django\core\handlers\base.py", line 197, in _get_response
    response = wrapped_callback(request, *callback_args, **callback_kwargs)
  File "C:\Users\shuri\AppData\Local\Programs\Python\Python39\lib\site-packages\django\views\generic\base.py", line 103, in view
    return self.dispatch(request, *args, **kwargs)
  File "C:\Users\shuri\AppData\Local\Programs\Python\Python39\lib\site-packages\django\views\generic\base.py", line 142, in dispatch
    return handler(request, *args, **kwargs)
  File "C:\Users\shuri\AppData\Local\Programs\Python\Python39\lib\site-packages\django\views\generic\edit.py", line 203, in get
    self.object = self.get_object()
  File "C:\Users\shuri\PycharmProjects\python_django\mysite\myauth\views.py", line 43, in get_object
    return self.request.user.profile
  File "C:\Users\shuri\AppData\Local\Programs\Python\Python39\lib\site-packages\django\utils\functional.py", line 268, in inner
    return func(_wrapped, *args)
AttributeError: 'AnonymousUser' object has no attribute 'profile'
2024-02-08 11:26:31,080 [ERROR] django.request: Internal Server Error: /ru/myauth/about-me/
Traceback (most recent call last):
  File "C:\Users\shuri\AppData\Local\Programs\Python\Python39\lib\site-packages\django\core\handlers\exception.py", line 55, in inner
    response = get_response(request)
  File "C:\Users\shuri\AppData\Local\Programs\Python\Python39\lib\site-packages\django\core\handlers\base.py", line 197, in _get_response
    response = wrapped_callback(request, *callback_args, **callback_kwargs)
  File "C:\Users\shuri\AppData\Local\Programs\Python\Python39\lib\site-packages\django\views\generic\base.py", line 103, in view
    return self.dispatch(request, *args, **kwargs)
  File "C:\Users\shuri\AppData\Local\Programs\Python\Python39\lib\site-packages\django\views\generic\base.py", line 142, in dispatch
    return handler(request, *args, **kwargs)
  File "C:\Users\shuri\AppData\Local\Programs\Python\Python39\lib\site-packages\django\views\generic\edit.py", line 203, in get
    self.object = self.get_object()
  File "C:\Users\shuri\PycharmProjects\python_django\mysite\myauth\views.py", line 43, in get_object
    return self.request.user.profile
  File "C:\Users\shuri\AppData\Local\Programs\Python\Python39\lib\site-packages\django\utils\functional.py", line 268, in inner
    return func(_wrapped, *args)
AttributeError: 'AnonymousUser' object has no attribute 'profile'
2024-02-08 11:26:58,560 [ERROR] django.request: Internal Server Error: /ru/myauth/about-me/
Traceback (most recent call last):
  File "C:\Users\shuri\AppData\Local\Programs\Python\Python39\lib\site-packages\django\core\handlers\exception.py", line 55, in inner
    response = get_response(request)
  File "C:\Users\shuri\AppData\Local\Programs\Python\Python39\lib\site-packages\django\core\handlers\base.py", line 197, in _get_response
    response = wrapped_callback(request, *callback_args, **callback_kwargs)
  File "C:\Users\shuri\AppData\Local\Programs\Python\Python39\lib\site-packages\django\views\generic\base.py", line 103, in view
    return self.dispatch(request, *args, **kwargs)
  File "C:\Users\shuri\AppData\Local\Programs\Python\Python39\lib\site-packages\django\views\generic\base.py", line 142, in dispatch
    return handler(request, *args, **kwargs)
  File "C:\Users\shuri\AppData\Local\Programs\Python\Python39\lib\site-packages\django\views\generic\edit.py", line 203, in get
    self.object = self.get_object()
  File "C:\Users\shuri\PycharmProjects\python_django\mysite\myauth\views.py", line 43, in get_object
    return self.request.user.profile
  File "C:\Users\shuri\AppData\Local\Programs\Python\Python39\lib\site-packages\django\utils\functional.py", line 268, in inner
    return func(_wrapped, *args)
  File "C:\Users\shuri\AppData\Local\Programs\Python\Python39\lib\site-packages\django\db\models\fields\related_descriptors.py", line 463, in __get__
    raise self.RelatedObjectDoesNotExist(
django.contrib.auth.models.User.profile.RelatedObjectDoesNotExist: User has no profile.
2024-02-08 11:34:20,300 [ERROR] django.request: Internal Server Error: /ru/myauth/about-me/
Traceback (most recent call last):
  File "C:\Users\shuri\AppData\Local\Programs\Python\Python39\lib\site-packages\django\core\handlers\exception.py", line 55, in inner
    response = get_response(request)
  File "C:\Users\shuri\AppData\Local\Programs\Python\Python39\lib\site-packages\django\core\handlers\base.py", line 197, in _get_response
    response = wrapped_callback(request, *callback_args, **callback_kwargs)
  File "C:\Users\shuri\AppData\Local\Programs\Python\Python39\lib\site-packages\django\views\generic\base.py", line 103, in view
    return self.dispatch(request, *args, **kwargs)
  File "C:\Users\shuri\AppData\Local\Programs\Python\Python39\lib\site-packages\django\views\generic\base.py", line 142, in dispatch
    return handler(request, *args, **kwargs)
  File "C:\Users\shuri\AppData\Local\Programs\Python\Python39\lib\site-packages\django\views\generic\edit.py", line 203, in get
    self.object = self.get_object()
  File "C:\Users\shuri\PycharmProjects\python_django\mysite\myauth\views.py", line 43, in get_object
    return self.request.user.profile
  File "C:\Users\shuri\AppData\Local\Programs\Python\Python39\lib\site-packages\django\utils\functional.py", line 268, in inner
    return func(_wrapped, *args)
  File "C:\Users\shuri\AppData\Local\Programs\Python\Python39\lib\site-packages\django\db\models\fields\related_descriptors.py", line 463, in __get__
    raise self.RelatedObjectDoesNotExist(
django.contrib.auth.models.User.profile.RelatedObjectDoesNotExist: User has no profile.
2024-02-08 11:35:56,956 [ERROR] django.request: Internal Server Error: /ru/myauth/about-me/
Traceback (most recent call last):
  File "C:\Users\shuri\AppData\Local\Programs\Python\Python39\lib\site-packages\django\core\handlers\exception.py", line 55, in inner
    response = get_response(request)
  File "C:\Users\shuri\AppData\Local\Programs\Python\Python39\lib\site-packages\django\core\handlers\base.py", line 197, in _get_response
    response = wrapped_callback(request, *callback_args, **callback_kwargs)
  File "C:\Users\shuri\AppData\Local\Programs\Python\Python39\lib\site-packages\django\views\generic\base.py", line 103, in view
    return self.dispatch(request, *args, **kwargs)
  File "C:\Users\shuri\AppData\Local\Programs\Python\Python39\lib\site-packages\django\views\generic\base.py", line 142, in dispatch
    return handler(request, *args, **kwargs)
  File "C:\Users\shuri\AppData\Local\Programs\Python\Python39\lib\site-packages\django\views\generic\edit.py", line 203, in get
    self.object = self.get_object()
  File "C:\Users\shuri\PycharmProjects\python_django\mysite\myauth\views.py", line 43, in get_object
    return self.request.user.profile
  File "C:\Users\shuri\AppData\Local\Programs\Python\Python39\lib\site-packages\django\utils\functional.py", line 268, in inner
    return func(_wrapped, *args)
  File "C:\Users\shuri\AppData\Local\Programs\Python\Python39\lib\site-packages\django\db\models\fields\related_descriptors.py", line 463, in __get__
    raise self.RelatedObjectDoesNotExist(
django.contrib.auth.models.User.profile.RelatedObjectDoesNotExist: User has no profile.
2024-02-08 11:42:44,046 [INFO] django.utils.autoreload: C:\Users\shuri\PycharmProjects\python_django\mysite\shopapp\views.py changed, reloading.
2024-02-08 11:42:46,637 [INFO] django.utils.autoreload: Watching for file changes with StatReloader
2024-02-08 11:42:53,454 [INFO] shopapp.views: Rendering shop index
2024-02-08 11:43:07,633 [ERROR] django.request: Internal Server Error: /ru/shop/orders/export/
Traceback (most recent call last):
  File "C:\Users\shuri\AppData\Local\Programs\Python\Python39\lib\site-packages\django\core\handlers\exception.py", line 55, in inner
    response = get_response(request)
  File "C:\Users\shuri\AppData\Local\Programs\Python\Python39\lib\site-packages\django\core\handlers\base.py", line 197, in _get_response
    response = wrapped_callback(request, *callback_args, **callback_kwargs)
  File "C:\Users\shuri\AppData\Local\Programs\Python\Python39\lib\site-packages\django\views\generic\base.py", line 103, in view
    return self.dispatch(request, *args, **kwargs)
  File "C:\Users\shuri\AppData\Local\Programs\Python\Python39\lib\site-packages\django\views\generic\base.py", line 142, in dispatch
    return handler(request, *args, **kwargs)
  File "C:\Users\shuri\PycharmProjects\python_django\mysite\shopapp\views.py", line 316, in get
    cache.set(cache_key, orders_data, 300)
  File "C:\Users\shuri\AppData\Local\Programs\Python\Python39\lib\site-packages\debug_toolbar\panels\cache.py", line 42, in wrapper
    return panel._record_call(cache, name, original_method, args, kwargs)
  File "C:\Users\shuri\AppData\Local\Programs\Python\Python39\lib\site-packages\debug_toolbar\panels\cache.py", line 149, in _record_call
    value = original_method(*args, **kwargs)
  File "C:\Users\shuri\AppData\Local\Programs\Python\Python39\lib\site-packages\django\core\cache\backends\filebased.py", line 54, in set
    self._write_content(f, timeout, value)
  File "C:\Users\shuri\AppData\Local\Programs\Python\Python39\lib\site-packages\django\core\cache\backends\filebased.py", line 44, in _write_content
    file.write(zlib.compress(pickle.dumps(value, self.pickle_protocol)))
AttributeError: Can't pickle local object 'create_forward_many_to_many_manager.<locals>.ManyRelatedManager'
2024-02-08 11:43:51,828 [INFO] django.utils.autoreload: C:\Users\shuri\PycharmProjects\python_django\mysite\shopapp\views.py changed, reloading.
2024-02-08 11:43:53,370 [INFO] django.utils.autoreload: Watching for file changes with StatReloader
2024-02-08 11:43:55,324 [ERROR] django.request: Internal Server Error: /ru/shop/orders/export/
Traceback (most recent call last):
  File "C:\Users\shuri\AppData\Local\Programs\Python\Python39\lib\site-packages\django\core\handlers\exception.py", line 55, in inner
    response = get_response(request)
  File "C:\Users\shuri\AppData\Local\Programs\Python\Python39\lib\site-packages\django\core\handlers\base.py", line 197, in _get_response
    response = wrapped_callback(request, *callback_args, **callback_kwargs)
  File "C:\Users\shuri\AppData\Local\Programs\Python\Python39\lib\site-packages\django\views\generic\base.py", line 103, in view
    return self.dispatch(request, *args, **kwargs)
  File "C:\Users\shuri\AppData\Local\Programs\Python\Python39\lib\site-packages\django\views\generic\base.py", line 142, in dispatch
    return handler(request, *args, **kwargs)
  File "C:\Users\shuri\PycharmProjects\python_django\mysite\shopapp\views.py", line 314, in get
    return JsonResponse({'orders': orders_data})
  File "C:\Users\shuri\AppData\Local\Programs\Python\Python39\lib\site-packages\django\http\response.py", line 691, in __init__
    data = json.dumps(data, cls=encoder, **json_dumps_params)
  File "C:\Users\shuri\AppData\Local\Programs\Python\Python39\lib\json\__init__.py", line 234, in dumps
    return cls(
  File "C:\Users\shuri\AppData\Local\Programs\Python\Python39\lib\json\encoder.py", line 199, in encode
    chunks = self.iterencode(o, _one_shot=True)
  File "C:\Users\shuri\AppData\Local\Programs\Python\Python39\lib\json\encoder.py", line 257, in iterencode
    return _iterencode(o, 0)
  File "C:\Users\shuri\AppData\Local\Programs\Python\Python39\lib\site-packages\django\core\serializers\json.py", line 106, in default
    return super().default(o)
  File "C:\Users\shuri\AppData\Local\Programs\Python\Python39\lib\json\encoder.py", line 179, in default
    raise TypeError(f'Object of type {o.__class__.__name__} '
TypeError: Object of type User is not JSON serializable
2024-02-08 11:44:39,175 [INFO] django.utils.autoreload: C:\Users\shuri\PycharmProjects\python_django\mysite\shopapp\views.py changed, reloading.
2024-02-08 11:44:40,600 [INFO] django.utils.autoreload: Watching for file changes with StatReloader
